Workbook

Sheet Legend
A1: Frontend Syllabus · HTML → CSS → JavaScript → TypeScript → React
A2: Built for Devang · merged from Frontend Masters (now Master.dev), Scrimba's MDN-curated career path, and the MDN Curriculum · 20 September 2026
A3: ▸ Legend | B3: Core 0–5 | C3: Advanced | D3: Branches | E3: Drills | F3: Courses | G3: Dashboard
A5: How to read every row
A6: Each row carries three tags: WHEN it starts being asked, HOW WELL you need to know it, and HOW OFTEN it comes up.
A8: YOE band | B8: What it means in an interview
A9: 0–1 | B9: Foundation. Fair game from an internship interview onward, and still expected at 3 YOE. Fumbling these ends a loop regardless of your years.
A10: 1–3 | B10: Applied professional level. This is the bulk of your interviews right now.
A11: 3–5 | B11: Senior-leaning. Not required at 3 YOE, but a demanding panel may probe it as a ceiling test.
A12: 5+ | B12: Lead / staff scope. Not a prerequisite for any role you are targeting today.
A13: Branch | B13: Depends on the job description, not on tenure. A Vue beginner topic is still a beginner topic.
A15: Depth | B15: What the interviewer is testing
A16: B — Build | B16: Implement it independently, with API documentation open. You do not need to recite the signature.
A17: D — Debug | B17: Build it, explain how it executes, diagnose a broken example, and argue the tradeoffs. The gotcha rows.
A18: E — Explain | B18: Explain it accurately and say when you would reach for it. Implementing its internals is unnecessary.
A20: Weight | B20: How often it actually comes up
A21: Core | B21: Asked in most interviews at that level. Non-negotiable.
... A23: Rare | B23: Occasional. A differentiator, not a gate.
A39: Status → Score (the dropdown on every sheet writes into this scale)
B40: Status | C40: Score | D40: What it means
B41: Not started | C41: 0 | D41: I have not learned it.
B42: Learning | C42: 1 | D42: I recognise the term or can repeat a definition.
B43: Can build | C43: 2 | D43: I can complete a familiar example with help.
B44: Can debug | C44: 3 | D44: I can implement it independently with docs and explain the important behaviour.
B45: Solid | C45: 4 | D45: I can debug unfamiliar failures, test edge cases and argue the tradeoffs.
B47: Target: score 3 on every B row, 4 on every D row, and an accurate one-paragraph answer on every E row. You do not need a 4 on everything to start applying.
A49: How to use this workbook
A50: • | B50: Work down Core Syllabus in order. The sheet is already sorted HTML → CSS → JavaScript → TypeScript → React → production.
A51: • | B51: Set Status from the dropdown in column I. Score fills itself from the table above, and the Dashboard updates.
A52: • | B52: Filter column G to Core when you are short on time. Those rows are the ones that decide most interviews.
A53: • | B53: Filter column F to D to drill the gotcha rows — the ones where an interviewer follows up with 'why?'.
A54: • | B54: Ignore Advanced Web until you have an offer. It is a roadmap, not a gate.
A55: • | B55: Open Role Branches only when a job description names that stack, then treat that branch as core for that application.
A56: • | B56: Column K is yours. Put the link to the exercise you solved, or the thing you got wrong, so revision has something to bite on.
A58: Scope, honestly
A59: — | B59: Every YOE label is an editorial preparation estimate. Neither platform publishes a concept-by-concept YOE scale, and no hiring data was measured. A label is not a promise that a topic cannot be asked earlier — demanding panels ask graph and DP questions of graduates.
A60: — | B60: The catalogue review was thorough at concept level: the full lesson trees of ~45 Master.dev courses via its course API, and Scrimba's complete career-path lesson list decoded from its path data. It is not a certified transcription of every video in either subscription.
A61: — | B61: Depth codes (B/D/E) are defaults derived from how each row behaves in an interview, then hand-checked on the high-value rows. Disagree with one and change it — that is what column F is for.
A62: — | B62: Frontend Masters rebranded to Master.dev during this research; frontendmasters.com redirects there. Course titles are as observed on 20 September 2026.
A63: — | B63: Version-sensitive areas — React 19, Next.js caching, Angular signals, Svelte runes — age fast. Check the installed version's docs before copying any API from a tutorial.
...

Sheet Core Syllabus
A1: Core Syllabus · 0–1 → 3–5 YOE
A2: The main track: HTML → CSS → JavaScript → TypeScript → React → production. Everything here is fair game at 3 YOE. Filter column E for a band, column G for interview frequency.
A3: Legend | C3: ▸ Core 0–5 | D3: Advanced | E3: Branches | H3: Drills | I3: Courses | K3: Dashboard
A4: # | B4: Area | C4: Section | D4: Concept | E4: YOE | F4: Depth | G4: Weight | H4: What interviewers actually ask | I4: Status | J4: Score | K4: My notes
A5: 1 | B5: Part 0 — How the Web Works | D5: Client / server model | E5: 0–1 | F5: B | G5: Core | H5: Draw what happens between typing a URL and seeing pixels | J5: {=IF($I5="","",IFERROR(INDEX(Legend!$C$41:$C$45,MATCH($I5,Legend!$B$41:$B$45,0)),""))}
A6: 2 | B6: Part 0 — How the Web Works | D6: DNS resolution | E6: 0–1 | F6: B | G6: Common | H6: "What happens when you type google.com" — the full walkthrough | J6: {=IF($I6="","",IFERROR(INDEX(Legend!$C$41:$C$45,MATCH($I6,Legend!$B$41:$B$45,0)),""))}
A7: 3 | B7: Part 0 — How the Web Works | D7: URL anatomy (scheme, host, port, path, query, hash) | E7: 0–1 | F7: D | G7: Core | H7: Parse a URL; what the hash does vs the query string | J7: {=IF($I7="","",IFERROR(INDEX(Legend!$C$41:$C$45,MATCH($I7,Legend!$B$41:$B$45,0)),""))}
A8: 4 | B8: Part 0 — How the Web Works | D8: HTTP request/response cycle | E8: 0–1 | F8: B | G8: Core | H8: Headers, body, method, status line | J8: {=IF($I8="","",IFERROR(INDEX(Legend!$C$41:$C$45,MATCH($I8,Legend!$B$41:$B$45,0)),""))}
A9: 5 | B9: Part 0 — How the Web Works | D9: HTTPS / TLS at a high level | E9: 1–3 | F9: E | G9: Common | H9: Why HTTPS, what the certificate proves | J9: {=IF($I9="","",IFERROR(INDEX(Legend!$C$41:$C$45,MATCH($I9,Legend!$B$41:$B$45,0)),""))}
A10: 6 | B10: Part 0 — How the Web Works | D10: Browser engine vs JS engine | E10: 1–3 | F10: D | G10: Common | H10: Chromium/Blink vs V8; who owns what | J10: {=IF($I10="","",IFERROR(INDEX(Legend!$C$41:$C$45,MATCH($I10,Legend!$B$41:$B$45,0)),""))}
A11: 7 | B11: Part 0 — How the Web Works | D11: Critical rendering path | E11: 1–3 | F11: B | G11: Core | H11: HTML → DOM, CSS → CSSOM, Render tree, Layout, Paint, Composite | J11: {=IF($I11="","",IFERROR(INDEX(Legend!$C$41:$C$45,MATCH($I11,Legend!$B$41:$B$45,0)),""))}
A12: 8 | B12: Part 0 — How the Web Works | D12: Parser blocking: <script> vs async vs defer | E12: 1–3 | F12: D | G12: Core | H12: Where to put script tags and why | J12: {=IF($I12="","",IFERROR(INDEX(Legend!$C$41:$C$45,MATCH($I12,Legend!$B$41:$B$45,0)),""))}
A13: 9 | B13: Part 0 — How the Web Works | D13: Web standards bodies (W3C, WHATWG, TC39) | E13: 0–1 | F13: E | G13: Rare | H13: Only ever asked as trivia | J13: {=IF($I13="","",IFERROR(INDEX(Legend!$C$41:$C$45,MATCH($I13,Legend!$B$41:$B$45,0)),""))}
A14: 10 | B14: Part 0 — How the Web Works | D14: Progressive enhancement vs graceful degradation | E14: 1–3 | F14: E | G14: Rare | H14: Usually in a11y or "old browser" discussions | J14: {=IF($I14="","",IFERROR(INDEX(Legend!$C$41:$C$45,MATCH($I14,Legend!$B$41:$B$45,0)),""))}
A15: 11 | B15: Part 0 — How the Web Works | D15: Static hosting vs a server vs a CDN | E15: 1–3 | F15: D | G15: Common | H15: Where does your build output actually live | J15: {=IF($I15="","",IFERROR(INDEX(Legend!$C$41:$C$45,MATCH($I15,Legend!$B$41:$B$45,0)),""))}
A16: 12 | B16: Part 1 — HTML | C16: 1.1 Document fundamentals | D16: <!DOCTYPE html> and quirks mode | E16: 0–1 | F16: B | G16: Common | H16: What happens if you omit it | J16: {=IF($I16="","",IFERROR(INDEX(Legend!$C$41:$C$45,MATCH($I16,Legend!$B$41:$B$45,0)),""))}
A17: 13 | B17: Part 1 — HTML | C17: 1.1 Document fundamentals | D17: Document skeleton: html / head / body | E17: 0–1 | F17: B | G17: Core | J17: {=IF($I17="","",IFERROR(INDEX(Legend!$C$41:$C$45,MATCH($I17,Legend!$B$41:$B$45,0)),""))}
A18: 14 | B18: Part 1 — HTML | C18: 1.1 Document fundamentals | D18: Tags, elements, attributes, void elements | E18: 0–1 | F18: B | G18: Core | J18: {=IF($I18="","",IFERROR(INDEX(Legend!$C$41:$C$45,MATCH($I18,Legend!$B$41:$B$45,0)),""))}
A19: 15 | B19: Part 1 — HTML | C19: 1.1 Document fundamentals | D19: Nesting rules & valid document structure | E19: 0–1 | F19: B | G19: Core | H19: Spot the invalid markup | J19: {=IF($I19="","",IFERROR(INDEX(Legend!$C$41:$C$45,MATCH($I19,Legend!$B$41:$B$45,0)),""))}
A20: 16 | B20: Part 1 — HTML | C20: 1.1 Document fundamentals | D20: Comments | E20: 0–1 | F20: E | G20: Rare | J20: {=IF($I20="","",IFERROR(INDEX(Legend!$C$41:$C$45,MATCH($I20,Legend!$B$41:$B$45,0)),""))}
A21: 17 | B21: Part 1 — HTML | C21: 1.1 Document fundamentals | D21: Block vs inline vs inline-block elements | E21: 0–1 | F21: D | G21: Core | H21: Classic: why won't my <span> take a width | J21: {=IF($I21="","",IFERROR(INDEX(Legend!$C$41:$C$45,MATCH($I21,Legend!$B$41:$B$45,0)),""))}
A22: 18 | B22: Part 1 — HTML | C22: 1.1 Document fundamentals | D22: Global attributes (id, class, title, hidden, tabindex) | E22: 0–1 | F22: B | G22: Core | J22: {=IF($I22="","",IFERROR(INDEX(Legend!$C$41:$C$45,MATCH($I22,Legend!$B$41:$B$45,0)),""))}
A23: 19 | B23: Part 1 — HTML | C23: 1.1 Document fundamentals | D23: data-* attributes and dataset | E23: 1–3 | F23: B | G23: Core | H23: Event delegation almost always needs this | J23: {=IF($I23="","",IFERROR(INDEX(Legend!$C$41:$C$45,MATCH($I23,Legend!$B$41:$B$45,0)),""))}
A24: 20 | B24: Part 1 — HTML | C24: 1.1 Document fundamentals | D24: lang attribute | E24: 1–3 | F24: B | G24: Common | H24: a11y question | J24: {=IF($I24="","",IFERROR(INDEX(Legend!$C$41:$C$45,MATCH($I24,Legend!$B$41:$B$45,0)),""))}
A25: 21 | B25: Part 1 — HTML | C25: 1.1 Document fundamentals | D25: Character entities & escaping | E25: 0–1 | F25: E | G25: Rare | H25: &amp;, &lt;, &nbsp; | J25: {=IF($I25="","",IFERROR(INDEX(Legend!$C$41:$C$45,MATCH($I25,Legend!$B$41:$B$45,0)),""))}
A26: 22 | B26: Part 1 — HTML | C26: 1.1 Document fundamentals | D26: HTML validation | E26: 1–3 | F26: E | G26: Rare | J26: {=IF($I26="","",IFERROR(INDEX(Legend!$C$41:$C$45,MATCH($I26,Legend!$B$41:$B$45,0)),""))}
A27: 23 | B27: Part 1 — HTML | C27: 1.2 Text & content semantics | D27: Headings h1–h6 and heading order | E27: 0–1 | F27: D | G27: Core | H27: Why only one h1; why you never skip levels | J27: {=IF($I27="","",IFERROR(INDEX(Legend!$C$41:$C$45,MATCH($I27,Legend!$B$41:$B$45,0)),""))}
A28: 24 | B28: Part 1 — HTML | C28: 1.2 Text & content semantics | D28: p, br, hr, whitespace collapsing | E28: 0–1 | F28: B | G28: Core | J28: {=IF($I28="","",IFERROR(INDEX(Legend!$C$41:$C$45,MATCH($I28,Legend!$B$41:$B$45,0)),""))}
A29: 25 | B29: Part 1 — HTML | C29: 1.2 Text & content semantics | D29: strong vs b, em vs i | E29: 0–1 | F29: D | G29: Core | H29: Semantics vs presentation — a favourite | J29: {=IF($I29="","",IFERROR(INDEX(Legend!$C$41:$C$45,MATCH($I29,Legend!$B$41:$B$45,0)),""))}
A30: 26 | B30: Part 1 — HTML | C30: 1.2 Text & content semantics | D30: ul, ol, li, dl/dt/dd | E30: 0–1 | F30: B | G30: Core | H30: Description lists get asked more than you'd expect | J30: {=IF($I30="","",IFERROR(INDEX(Legend!$C$41:$C$45,MATCH($I30,Legend!$B$41:$B$45,0)),""))}
A31: 27 | B31: Part 1 — HTML | C31: 1.2 Text & content semantics | D31: blockquote, q, cite | E31: 0–1 | F31: E | G31: Rare | J31: {=IF($I31="","",IFERROR(INDEX(Legend!$C$41:$C$45,MATCH($I31,Legend!$B$41:$B$45,0)),""))}
A32: 28 | B32: Part 1 — HTML | C32: 1.2 Text & content semantics | D32: code, pre, kbd, samp | E32: 0–1 | F32: E | G32: Rare | J32: {=IF($I32="","",IFERROR(INDEX(Legend!$C$41:$C$45,MATCH($I32,Legend!$B$41:$B$45,0)),""))}
A33: 29 | B33: Part 1 — HTML | C33: 1.2 Text & content semantics | D33: abbr, time, mark, small, sub, sup | E33: 1–3 | F33: E | G33: Rare | J33: {=IF($I33="","",IFERROR(INDEX(Legend!$C$41:$C$45,MATCH($I33,Legend!$B$41:$B$45,0)),""))}
A34: 30 | B34: Part 1 — HTML | C34: 1.2 Text & content semantics | D34: span and div as the non-semantic fallbacks | E34: 0–1 | F34: B | G34: Core | H34: "When do you reach for a div" | J34: {=IF($I34="","",IFERROR(INDEX(Legend!$C$41:$C$45,MATCH($I34,Legend!$B$41:$B$45,0)),""))}
A35: 31 | B35: Part 1 — HTML | C35: 1.2 Text & content semantics | D35: details / summary (native disclosure) | E35: 1–3 | F35: B | G35: Common | H35: Build an accordion without JS | J35: {=IF($I35="","",IFERROR(INDEX(Legend!$C$41:$C$45,MATCH($I35,Legend!$B$41:$B$45,0)),""))}
A36: 32 | B36: Part 1 — HTML | C36: 1.2 Text & content semantics | D36: dialog element + showModal() | E36: 1–3 | F36: B | G36: Common | H36: Modals without a library | J36: {=IF($I36="","",IFERROR(INDEX(Legend!$C$41:$C$45,MATCH($I36,Legend!$B$41:$B$45,0)),""))}
A37: 33 | B37: Part 1 — HTML | C37: 1.3 Links & navigation | D37: <a href>, absolute vs relative vs root-relative paths | E37: 0–1 | F37: D | G37: Core | J37: {=IF($I37="","",IFERROR(INDEX(Legend!$C$41:$C$45,MATCH($I37,Legend!$B$41:$B$45,0)),""))}
A38: 34 | B38: Part 1 — HTML | C38: 1.3 Links & navigation | D38: Fragment links / anchors | E38: 0–1 | F38: B | G38: Common | J38: {=IF($I38="","",IFERROR(INDEX(Legend!$C$41:$C$45,MATCH($I38,Legend!$B$41:$B$45,0)),""))}
A39: 35 | B39: Part 1 — HTML | C39: 1.3 Links & navigation | D39: target="_blank" + rel="noopener noreferrer" | E39: 1–3 | F39: B | G39: Core | H39: The security question. window.opener hijacking | J39: {=IF($I39="","",IFERROR(INDEX(Legend!$C$41:$C$45,MATCH($I39,Legend!$B$41:$B$45,0)),""))}
A40: 36 | B40: Part 1 — HTML | C40: 1.3 Links & navigation | D40: rel values: nofollow, canonical, preload, prefetch | E40: 1–3 | F40: B | G40: Common | H40: SEO + perf overlap | J40: {=IF($I40="","",IFERROR(INDEX(Legend!$C$41:$C$45,MATCH($I40,Legend!$B$41:$B$45,0)),""))}
...

Sheet Advanced Web
A1: Advanced Web · 5+ YOE and deep specialisation
A2: Not required at 3 YOE. Post-offer roadmap, plus the ceiling-test topics a senior interviewer may probe for a one-paragraph answer.
A3: Legend | C3: Core 0–5 | D3: ▸ Advanced | E3: Branches | H3: Drills | I3: Courses | K3: Dashboard
A4: # | B4: Area | C4: Section | D4: Concept | E4: YOE | F4: Depth | G4: Weight | H4: What interviewers actually ask | I4: Status | J4: Score | K4: My notes
A5: 1 | B5: Advanced Web | C5: A1 — Advanced CSS | D5: @property typed custom properties | E5: 3–5 | F5: E | G5: Rare | H5: Enables animating gradients and custom values | J5: {=IF($I5="","",IFERROR(INDEX(Legend!$C$41:$C$45,MATCH($I5,Legend!$B$41:$B$45,0)),""))}
A6: 2 | B6: Advanced Web | C6: A1 — Advanced CSS | D6: Container style queries | E6: 3–5 | F6: E | G6: Rare | H6: Still landing across browsers | J6: {=IF($I6="","",IFERROR(INDEX(Legend!$C$41:$C$45,MATCH($I6,Legend!$B$41:$B$45,0)),""))}
A7: 3 | B7: Advanced Web | C7: A1 — Advanced CSS | D7: View Transitions API ⚑ | E7: 3–5 | F7: E | G7: Rare | H7: Cross-document and SPA transitions | J7: {=IF($I7="","",IFERROR(INDEX(Legend!$C$41:$C$45,MATCH($I7,Legend!$B$41:$B$45,0)),""))}
A8: 4 | B8: Advanced Web | C8: A1 — Advanced CSS | D8: @scope | E8: 3–5 | F8: E | G8: Rare | J8: {=IF($I8="","",IFERROR(INDEX(Legend!$C$41:$C$45,MATCH($I8,Legend!$B$41:$B$45,0)),""))}
A9: 5 | B9: Advanced Web | C9: A1 — Advanced CSS | D9: Anchor positioning | E9: 3–5 | F9: E | G9: Rare | H9: Native tooltip/popover placement | J9: {=IF($I9="","",IFERROR(INDEX(Legend!$C$41:$C$45,MATCH($I9,Legend!$B$41:$B$45,0)),""))}
A10: 6 | B10: Advanced Web | C10: A1 — Advanced CSS | D10: @starting-style & transitioning display | E10: 3–5 | F10: E | G10: Rare | J10: {=IF($I10="","",IFERROR(INDEX(Legend!$C$41:$C$45,MATCH($I10,Legend!$B$41:$B$45,0)),""))}
A11: 7 | B11: Advanced Web | C11: A1 — Advanced CSS | D11: Popover API | E11: 3–5 | F11: E | G11: Rare | J11: {=IF($I11="","",IFERROR(INDEX(Legend!$C$41:$C$45,MATCH($I11,Legend!$B$41:$B$45,0)),""))}
A12: 8 | B12: Advanced Web | C12: A1 — Advanced CSS | D12: Houdini (Paint / Layout / Properties APIs) | E12: 5+ | F12: E | G12: Rare | J12: {=IF($I12="","",IFERROR(INDEX(Legend!$C$41:$C$45,MATCH($I12,Legend!$B$41:$B$45,0)),""))}
A13: 9 | B13: Advanced Web | C13: A1 — Advanced CSS | D13: Scroll-driven animations (animation-timeline) | E13: 3–5 | F13: E | G13: Rare | J13: {=IF($I13="","",IFERROR(INDEX(Legend!$C$41:$C$45,MATCH($I13,Legend!$B$41:$B$45,0)),""))}
A14: 10 | B14: Advanced Web | C14: A1 — Advanced CSS | D14: FLIP technique | E14: 3–5 | F14: E | G14: Rare | H14: FEM's CSS Animations course; layout animation from first principles | J14: {=IF($I14="","",IFERROR(INDEX(Legend!$C$41:$C$45,MATCH($I14,Legend!$B$41:$B$45,0)),""))}
A15: 11 | B15: Advanced Web | C15: A1 — Advanced CSS | D15: Lerp / pointer-driven reactive animation | E15: 3–5 | F15: E | G15: Rare | J15: {=IF($I15="","",IFERROR(INDEX(Legend!$C$41:$C$45,MATCH($I15,Legend!$B$41:$B$45,0)),""))}
A16: 12 | B16: Advanced Web | C16: A1 — Advanced CSS | D16: SVG animation & SMIL; morphing | E16: 3–5 | F16: E | G16: Rare | J16: {=IF($I16="","",IFERROR(INDEX(Legend!$C$41:$C$45,MATCH($I16,Legend!$B$41:$B$45,0)),""))}
A17: 13 | B17: Advanced Web | C17: A1 — Advanced CSS | D17: Critical CSS extraction & inlining ⚑ | E17: 3–5 | F17: E | G17: Rare | H17: Above-the-fold render optimisation | J17: {=IF($I17="","",IFERROR(INDEX(Legend!$C$41:$C$45,MATCH($I17,Legend!$B$41:$B$45,0)),""))}
A18: 14 | B18: Advanced Web | C18: A1 — Advanced CSS | D18: Zero-runtime CSS-in-JS (vanilla-extract, Panda, Linaria) | E18: 3–5 | F18: E | G18: Rare | J18: {=IF($I18="","",IFERROR(INDEX(Legend!$C$41:$C$45,MATCH($I18,Legend!$B$41:$B$45,0)),""))}
A19: 15 | B19: Advanced Web | C19: A1 — Advanced CSS | D19: Building a design system from scratch: token pipeline, theming contract, docs site, versioning ⚑ | E19: 3–5 | F19: B | G19: Common | H19: FEM: Design Systems v2 — real senior work | J19: {=IF($I19="","",IFERROR(INDEX(Legend!$C$41:$C$45,MATCH($I19,Legend!$B$41:$B$45,0)),""))}
A20: 16 | B20: Advanced Web | C20: A1 — Advanced CSS | D20: Full RTL / bidirectional layout support | E20: 3–5 | F20: E | G20: Rare | J20: {=IF($I20="","",IFERROR(INDEX(Legend!$C$41:$C$45,MATCH($I20,Legend!$B$41:$B$45,0)),""))}
A21: 17 | B21: Advanced Web | C21: A1 — Advanced CSS | D21: Colour science: OKLCH, wide gamut, perceptual uniformity | E21: 5+ | F21: E | G21: Rare | J21: {=IF($I21="","",IFERROR(INDEX(Legend!$C$41:$C$45,MATCH($I21,Legend!$B$41:$B$45,0)),""))}
A22: 18 | B22: Advanced Web | C22: A2 — Advanced JavaScript & language internals | D22: Symbol.toPrimitive & metaprogramming with well-known symbols | E22: 3–5 | F22: E | G22: Rare | H22: FEM Hard Parts v3's metaprogramming chapter | J22: {=IF($I22="","",IFERROR(INDEX(Legend!$C$41:$C$45,MATCH($I22,Legend!$B$41:$B$45,0)),""))}
A23: 19 | B23: Advanced Web | C23: A2 — Advanced JavaScript & language internals | D23: Proxy + Reflect for building reactive systems ⚑ | E23: 3–5 | F23: B | G23: Common | H23: How Vue 3 and MobX work; a strong "how does reactivity work" answer | J23: {=IF($I23="","",IFERROR(INDEX(Legend!$C$41:$C$45,MATCH($I23,Legend!$B$41:$B$45,0)),""))}
A24: 20 | B24: Advanced Web | C24: A2 — Advanced JavaScript & language internals | D24: Async generators & for await…of | E24: 3–5 | F24: E | G24: Rare | H24: Streaming data | J24: {=IF($I24="","",IFERROR(INDEX(Legend!$C$41:$C$45,MATCH($I24,Legend!$B$41:$B$45,0)),""))}
A25: 21 | B25: Advanced Web | C25: A2 — Advanced JavaScript & language internals | D25: Iterators/generators for custom control flow & coroutines | E25: 3–5 | F25: E | G25: Rare | J25: {=IF($I25="","",IFERROR(INDEX(Legend!$C$41:$C$45,MATCH($I25,Legend!$B$41:$B$45,0)),""))}
A26: 22 | B26: Advanced Web | C26: A2 — Advanced JavaScript & language internals | D26: Tail calls, engine optimisation, hidden classes, inline caches | E26: 5+ | F26: E | G26: Rare | H26: FEM: Hardcore JS | J26: {=IF($I26="","",IFERROR(INDEX(Legend!$C$41:$C$45,MATCH($I26,Legend!$B$41:$B$45,0)),""))}
A27: 23 | B27: Advanced Web | C27: A2 — Advanced JavaScript & language internals | D27: Deoptimisation & megamorphic call sites | E27: 5+ | F27: E | G27: Rare | J27: {=IF($I27="","",IFERROR(INDEX(Legend!$C$41:$C$45,MATCH($I27,Legend!$B$41:$B$45,0)),""))}
A28: 24 | B28: Advanced Web | C28: A2 — Advanced JavaScript & language internals | D28: Typed arrays, ArrayBuffer, SharedArrayBuffer, Atomics | E28: 3–5 | F28: E | G28: Rare | J28: {=IF($I28="","",IFERROR(INDEX(Legend!$C$41:$C$45,MATCH($I28,Legend!$B$41:$B$45,0)),""))}
A29: 25 | B29: Advanced Web | C29: A2 — Advanced JavaScript & language internals | D29: WeakRef / FinalizationRegistry | E29: 5+ | F29: E | G29: Rare | J29: {=IF($I29="","",IFERROR(INDEX(Legend!$C$41:$C$45,MATCH($I29,Legend!$B$41:$B$45,0)),""))}
A30: 26 | B30: Advanced Web | C30: A2 — Advanced JavaScript & language internals | D30: Import maps & import attributes | E30: 3–5 | F30: E | G30: Rare | J30: {=IF($I30="","",IFERROR(INDEX(Legend!$C$41:$C$45,MATCH($I30,Legend!$B$41:$B$45,0)),""))}
A31: 27 | B31: Advanced Web | C31: A2 — Advanced JavaScript & language internals | D31: ReDoS / catastrophic backtracking | E31: 3–5 | F31: E | G31: Rare | J31: {=IF($I31="","",IFERROR(INDEX(Legend!$C$41:$C$45,MATCH($I31,Legend!$B$41:$B$45,0)),""))}
A32: 28 | B32: Advanced Web | C32: A2 — Advanced JavaScript & language internals | D32: Proper tail-recursive & trampolined recursion | E32: 5+ | F32: E | G32: Rare | J32: {=IF($I32="","",IFERROR(INDEX(Legend!$C$41:$C$45,MATCH($I32,Legend!$B$41:$B$45,0)),""))}
A33: 29 | B33: Advanced Web | C33: A2 — Advanced JavaScript & language internals | D33: Monads, functors, transducers, lenses | E33: 5+ | F33: E | G33: Rare | H33: FEM: Functional JavaScript v3 | J33: {=IF($I33="","",IFERROR(INDEX(Legend!$C$41:$C$45,MATCH($I33,Legend!$B$41:$B$45,0)),""))}
A34: 30 | B34: Advanced Web | C34: A2 — Advanced JavaScript & language internals | D34: Algebraic data types & pattern matching in JS | E34: 5+ | F34: E | G34: Rare | J34: {=IF($I34="","",IFERROR(INDEX(Legend!$C$41:$C$45,MATCH($I34,Legend!$B$41:$B$45,0)),""))}
A35: 31 | B35: Advanced Web | C35: A2 — Advanced JavaScript & language internals | D35: Writing a parser / interpreter / compiler ⚑ | E35: 5+ | F35: E | G35: Rare | H35: FEM: Building Your Own Programming Language | J35: {=IF($I35="","",IFERROR(INDEX(Legend!$C$41:$C$45,MATCH($I35,Legend!$B$41:$B$45,0)),""))}
A36: 32 | B36: Advanced Web | C36: A2 — Advanced JavaScript & language internals | D36: WebAssembly: what it is, when it wins, JS interop ⚑ | E36: 3–5 | F36: E | G36: Rare | H36: Awareness answer is enough | J36: {=IF($I36="","",IFERROR(INDEX(Legend!$C$41:$C$45,MATCH($I36,Legend!$B$41:$B$45,0)),""))}
A37: 33 | B37: Advanced Web | C37: A3 — Advanced React | D37: useSyncExternalStore ⚑ | E37: 3–5 | F37: B | G37: Common | H37: How Zustand/Redux subscribe safely under concurrent rendering | J37: {=IF($I37="","",IFERROR(INDEX(Legend!$C$41:$C$45,MATCH($I37,Legend!$B$41:$B$45,0)),""))}
A38: 34 | B38: Advanced Web | C38: A3 — Advanced React | D38: useImperativeHandle | E38: 3–5 | F38: E | G38: Rare | J38: {=IF($I38="","",IFERROR(INDEX(Legend!$C$41:$C$45,MATCH($I38,Legend!$B$41:$B$45,0)),""))}
A39: 35 | B39: Advanced Web | C39: A3 — Advanced React | D39: useDebugValue | E39: 3–5 | F39: E | G39: Rare | J39: {=IF($I39="","",IFERROR(INDEX(Legend!$C$41:$C$45,MATCH($I39,Legend!$B$41:$B$45,0)),""))}
A40: 36 | B40: Advanced Web | C40: A3 — Advanced React | D40: React Fiber internals: work loop, lanes, priority, time slicing ⚑ | E40: 3–5 | F40: B | G40: Common | H40: The deep answer behind "concurrent rendering" | J40: {=IF($I40="","",IFERROR(INDEX(Legend!$C$41:$C$45,MATCH($I40,Legend!$B$41:$B$45,0)),""))}
...

Sheet Role Branches
A1: Role Branches · promote a branch when the JD names it
A2: Angular, Vue, Svelte, Next.js, backend, AI, browser platform, graphics. YOE here is branch-relative: a Vue beginner topic is still a beginner topic.
A3: Legend | C3: Core 0–5 | D3: Advanced | E3: ▸ Branches | H3: Drills | I3: Courses | K3: Dashboard
A4: # | B4: Area | C4: Section | D4: Concept | E4: YOE | F4: Depth | G4: Weight | H4: What interviewers actually ask | I4: Status | J4: Score | K4: My notes
A5: 1 | B5: AI Engineering | C5: AI branch | D5: AI API integration | E5: 1–3 | F5: B | G5: Common | H5: Server-side keys, prompts and messages, structured responses, streaming, failures | J5: {=IF($I5="","",IFERROR(INDEX(Legend!$C$41:$C$45,MATCH($I5,Legend!$B$41:$B$45,0)),""))}
A6: 2 | B6: AI Engineering | C6: AI branch | D6: AI chat UI | E6: 1–3 | F6: B | G6: Common | H6: Stream rendering, cancellation, partial output, retries, conversation state | J6: {=IF($I6="","",IFERROR(INDEX(Legend!$C$41:$C$45,MATCH($I6,Legend!$B$41:$B$45,0)),""))}
A7: 3 | B7: AI Engineering | C7: AI branch | D7: Structured output and tool calls | E7: 3–5 | F7: B | G7: Common | H7: Validate schemas, authorise actions, handle invalid model output | J7: {=IF($I7="","",IFERROR(INDEX(Legend!$C$41:$C$45,MATCH($I7,Legend!$B$41:$B$45,0)),""))}
A8: 4 | B8: AI Engineering | C8: AI branch | D8: RAG | E8: 3–5 | F8: B | G8: Common | H8: Ingestion, chunks, embeddings, retrieval, citations, evaluation | J8: {=IF($I8="","",IFERROR(INDEX(Legend!$C$41:$C$45,MATCH($I8,Legend!$B$41:$B$45,0)),""))}
A9: 5 | B9: AI Engineering | C9: AI branch | D9: Agents | E9: 3–5 | F9: B | G9: Common | H9: Tool loop, state, stopping conditions, budgets, human approval boundaries | J9: {=IF($I9="","",IFERROR(INDEX(Legend!$C$41:$C$45,MATCH($I9,Legend!$B$41:$B$45,0)),""))}
A10: 6 | B10: AI Engineering | C10: AI branch | D10: Context engineering | E10: 3–5 | F10: B | G10: Common | H10: Context selection, token budgets, summarisation, durable state | J10: {=IF($I10="","",IFERROR(INDEX(Legend!$C$41:$C$45,MATCH($I10,Legend!$B$41:$B$45,0)),""))}
A11: 7 | B11: AI Engineering | C11: AI branch | D11: MCP | E11: 3–5 | F11: B | G11: Common | H11: Tools and resources, client/server integration, authorisation, untrusted content | J11: {=IF($I11="","",IFERROR(INDEX(Legend!$C$41:$C$45,MATCH($I11,Legend!$B$41:$B$45,0)),""))}
A12: 8 | B12: AI Engineering | C12: AI branch | D12: Vercel AI SDK | E12: 1–3 | F12: B | G12: Common | H12: Model-provider interfaces and streaming UI primitives | J12: {=IF($I12="","",IFERROR(INDEX(Legend!$C$41:$C$45,MATCH($I12,Legend!$B$41:$B$45,0)),""))}
A13: 9 | B13: AI Engineering | C13: AI branch | D13: Multimodal AI | E13: 3–5 | F13: E | G13: Rare | H13: Image and audio inputs, generated assets, latency, cost, privacy | J13: {=IF($I13="","",IFERROR(INDEX(Legend!$C$41:$C$45,MATCH($I13,Legend!$B$41:$B$45,0)),""))}
A14: 10 | B14: AI Engineering | C14: AI branch | D14: AI evaluation and security | E14: 3–5 | F14: D | G14: Rare | H14: Prompt injection, data leakage, action authorisation, regression sets, observability | J14: {=IF($I14="","",IFERROR(INDEX(Legend!$C$41:$C$45,MATCH($I14,Legend!$B$41:$B$45,0)),""))}
A15: 11 | B15: AI Engineering | C15: AI branch | D15: Local models and harnesses | E15: 3–5 | F15: D | G15: Rare | H15: Model serving, tool orchestration, reproducible evals, hardware limits | J15: {=IF($I15="","",IFERROR(INDEX(Legend!$C$41:$C$45,MATCH($I15,Legend!$B$41:$B$45,0)),""))}
A16: 12 | B16: AI Engineering | C16: AI branch | D16: Never ship the API key | E16: 1–3 | F16: D | G16: Core | H16: The one AI mistake that will end an interview — proxy it server-side | J16: {=IF($I16="","",IFERROR(INDEX(Legend!$C$41:$C$45,MATCH($I16,Legend!$B$41:$B$45,0)),""))}
A17: 13 | B17: AI Engineering | C17: From advanced web | D17: Calling LLM APIs from a frontend safely (never ship the key) ⚑ | E17: 3–5 | F17: B | G17: Common | H17: Increasingly asked as a "have you touched AI" question | J17: {=IF($I17="","",IFERROR(INDEX(Legend!$C$41:$C$45,MATCH($I17,Legend!$B$41:$B$45,0)),""))}
A18: 14 | B18: AI Engineering | C18: From advanced web | D18: Streaming responses & token-by-token UI | E18: 3–5 | F18: B | G18: Common | J18: {=IF($I18="","",IFERROR(INDEX(Legend!$C$41:$C$45,MATCH($I18,Legend!$B$41:$B$45,0)),""))}
A19: 15 | B19: AI Engineering | C19: From advanced web | D19: Vercel AI SDK | E19: 3–5 | F19: B | G19: Common | J19: {=IF($I19="","",IFERROR(INDEX(Legend!$C$41:$C$45,MATCH($I19,Legend!$B$41:$B$45,0)),""))}
A20: 16 | B20: AI Engineering | C20: From advanced web | D20: Embeddings, vector stores, RAG fundamentals | E20: 3–5 | F20: E | G20: Rare | J20: {=IF($I20="","",IFERROR(INDEX(Legend!$C$41:$C$45,MATCH($I20,Legend!$B$41:$B$45,0)),""))}
A21: 17 | B21: AI Engineering | C21: From advanced web | D21: Agents & tool calling | E21: 5+ | F21: E | G21: Rare | J21: {=IF($I21="","",IFERROR(INDEX(Legend!$C$41:$C$45,MATCH($I21,Legend!$B$41:$B$45,0)),""))}
A22: 18 | B22: AI Engineering | C22: From advanced web | D22: Prompt injection & output sanitisation in the UI | E22: 3–5 | F22: E | G22: Rare | J22: {=IF($I22="","",IFERROR(INDEX(Legend!$C$41:$C$45,MATCH($I22,Legend!$B$41:$B$45,0)),""))}
A23: 19 | B23: Angular | C23: Angular branch | D23: Application structure | E23: 0–1 | F23: B | G23: Core | H23: CLI setup, bootstrap, components, templates, styles | J23: {=IF($I23="","",IFERROR(INDEX(Legend!$C$41:$C$45,MATCH($I23,Legend!$B$41:$B$45,0)),""))}
A24: 20 | B24: Angular | C24: Angular branch | D24: Template binding | E24: 0–1 | F24: B | G24: Core | H24: Interpolation, property, event and two-way binding | J24: {=IF($I24="","",IFERROR(INDEX(Legend!$C$41:$C$45,MATCH($I24,Legend!$B$41:$B$45,0)),""))}
A25: 21 | B25: Angular | C25: Angular branch | D25: Template control flow | E25: 0–1 | F25: B | G25: Core | H25: The conditional and loop syntax your project's version supports; stable tracking | J25: {=IF($I25="","",IFERROR(INDEX(Legend!$C$41:$C$45,MATCH($I25,Legend!$B$41:$B$45,0)),""))}
A26: 22 | B26: Angular | C26: Angular branch | D26: Standalone components | E26: 1–3 | F26: B | G26: Core | H26: Imports and composition; recognise older NgModule projects | J26: {=IF($I26="","",IFERROR(INDEX(Legend!$C$41:$C$45,MATCH($I26,Legend!$B$41:$B$45,0)),""))}
A27: 23 | B27: Angular | C27: Angular branch | D27: Component communication | E27: 1–3 | F27: B | G27: Core | H27: Inputs, outputs, model bindings, data ownership | J27: {=IF($I27="","",IFERROR(INDEX(Legend!$C$41:$C$45,MATCH($I27,Legend!$B$41:$B$45,0)),""))}
A28: 24 | B28: Angular | C28: Angular branch | D28: Directives and pipes | E28: 1–3 | F28: B | G28: Core | H28: Transform presentation, attach reusable behaviour | J28: {=IF($I28="","",IFERROR(INDEX(Legend!$C$41:$C$45,MATCH($I28,Legend!$B$41:$B$45,0)),""))}
A29: 25 | B29: Angular | C29: Angular branch | D29: Services | E29: 1–3 | F29: B | G29: Core | H29: Shared logic and data access with explicit boundaries | J29: {=IF($I29="","",IFERROR(INDEX(Legend!$C$41:$C$45,MATCH($I29,Legend!$B$41:$B$45,0)),""))}
A30: 26 | B30: Angular | C30: Angular branch | D30: Dependency injection | E30: 1–3 | F30: D | G30: Core | H30: Providers, injector hierarchy, tokens, scope, lifetime | J30: {=IF($I30="","",IFERROR(INDEX(Legend!$C$41:$C$45,MATCH($I30,Legend!$B$41:$B$45,0)),""))}
A31: 27 | B31: Angular | C31: Angular branch | D31: Lifecycle hooks | E31: 1–3 | F31: B | G31: Core | H31: Init, input changes, view readiness, destruction, cleanup | J31: {=IF($I31="","",IFERROR(INDEX(Legend!$C$41:$C$45,MATCH($I31,Legend!$B$41:$B$45,0)),""))}
A32: 28 | B32: Angular | C32: Angular branch | D32: Signals | E32: 1–3 | F32: B | G32: Core | H32: State, computed values, effects | J32: {=IF($I32="","",IFERROR(INDEX(Legend!$C$41:$C$45,MATCH($I32,Legend!$B$41:$B$45,0)),""))}
A33: 29 | B33: Angular | C33: Angular branch | D33: Derived reactive state | E33: 1–3 | F33: D | G33: Core | H33: Dependency tracking, propagation, avoiding redundant effects | J33: {=IF($I33="","",IFERROR(INDEX(Legend!$C$41:$C$45,MATCH($I33,Legend!$B$41:$B$45,0)),""))}
A34: 30 | B34: Angular | C34: Angular branch | D34: Linked signals | E34: 1–3 | F34: E | G34: Rare | H34: Dependent mutable state where supported; compare with computed | J34: {=IF($I34="","",IFERROR(INDEX(Legend!$C$41:$C$45,MATCH($I34,Legend!$B$41:$B$45,0)),""))}
... A83: 79 | B83: Backend & Infra | C83: Full-stack branch | D83: Other backend languages | E83: 1–3 | F83: B | G83: Rare | H83: Python, Go, Rust, Java, Ruby — separate tracks, not JS prerequisites | J83: {=IF($I83="","",IFERROR(INDEX(Legend!$C$41:$C$45,MATCH($I83,Legend!$B$41:$B$45,0)),""))}
A84: 80 | B84: Backend & Infra | C84: From advanced web | D84: Node.js runtime: event loop phases, streams, buffers, libuv ⚑ | E84: 3–5 | F84: B | G84: Common | J84: {=IF($I84="","",IFERROR(INDEX(Legend!$C$41:$C$45,MATCH($I84,Legend!$B$41:$B$45,0)),""))}
A85: 81 | B85: Backend & Infra | C85: From advanced web | D85: Express: routing, middleware, error handling | E85: 3–5 | F85: B | G85: Common | J85: {=IF($I85="","",IFERROR(INDEX(Legend!$C$41:$C$45,MATCH($I85,Legend!$B$41:$B$45,0)),""))}
A86: 82 | B86: Backend & Infra | C86: From advanced web | D86: REST API design & versioning at depth | E86: 3–5 | F86: B | G86: Common | J86: {=IF($I86="","",IFERROR(INDEX(Legend!$C$41:$C$45,MATCH($I86,Legend!$B$41:$B$45,0)),""))}
A87: 83 | B87: Backend & Infra | C87: From advanced web | D87: SQL & relational modelling; joins, indexes, transactions ⚑ | E87: 3–5 | F87: B | G87: Common | J87: {=IF($I87="","",IFERROR(INDEX(Legend!$C$41:$C$45,MATCH($I87,Legend!$B$41:$B$45,0)),""))}
A88: 84 | B88: Backend & Infra | C88: From advanced web | D88: Postgres / Supabase; ORMs (Prisma, Drizzle) | E88: 3–5 | F88: B | G88: Common | J88: {=IF($I88="","",IFERROR(INDEX(Legend!$C$41:$C$45,MATCH($I88,Legend!$B$41:$B$45,0)),""))}
...

Sheet Interview Drills
A1: Interview Drills · the delivery layer
A2: Polyfills, machine-coding rounds, DSA-lite, discussion rounds and portfolio evidence. Knowledge only converts if you can produce it under time pressure.
A3: Legend | C3: Core 0–5 | D3: Advanced | E3: Branches | H3: ▸ Drills | I3: Courses | K3: Dashboard
A4: # | B4: Area | C4: Section | D4: Concept | E4: YOE | F4: Depth | G4: Weight | H4: What interviewers actually ask | I4: Status | J4: Score | K4: My notes
A5: 1 | B5: Part 13 — Interview-Specific Practice | C5: 13.1 Polyfills & "implement it yourself" | D5: Array.prototype.map / filter / reduce / forEach | E5: 1–3 | F5: B | G5: Core | J5: {=IF($I5="","",IFERROR(INDEX(Legend!$C$41:$C$45,MATCH($I5,Legend!$B$41:$B$45,0)),""))}
A6: 2 | B6: Part 13 — Interview-Specific Practice | C6: 13.1 Polyfills & "implement it yourself" | D6: Function.prototype.call / apply / bind | E6: 1–3 | F6: B | G6: Core | J6: {=IF($I6="","",IFERROR(INDEX(Legend!$C$41:$C$45,MATCH($I6,Legend!$B$41:$B$45,0)),""))}
A7: 3 | B7: Part 13 — Interview-Specific Practice | C7: 13.1 Polyfills & "implement it yourself" | D7: Promise.all / allSettled / race / any | E7: 1–3 | F7: B | G7: Core | J7: {=IF($I7="","",IFERROR(INDEX(Legend!$C$41:$C$45,MATCH($I7,Legend!$B$41:$B$45,0)),""))}
A8: 4 | B8: Part 13 — Interview-Specific Practice | C8: 13.1 Polyfills & "implement it yourself" | D8: A minimal Promise class | E8: 1–3 | F8: B | G8: Common | H8: FEM's "Promise: basic logic → settling → execution" sequence | J8: {=IF($I8="","",IFERROR(INDEX(Legend!$C$41:$C$45,MATCH($I8,Legend!$B$41:$B$45,0)),""))}
A9: 5 | B9: Part 13 — Interview-Specific Practice | C9: 13.1 Polyfills & "implement it yourself" | D9: debounce / throttle | E9: 1–3 | F9: B | G9: Core | J9: {=IF($I9="","",IFERROR(INDEX(Legend!$C$41:$C$45,MATCH($I9,Legend!$B$41:$B$45,0)),""))}
A10: 6 | B10: Part 13 — Interview-Specific Practice | C10: 13.1 Polyfills & "implement it yourself" | D10: deepClone / deepEqual | E10: 1–3 | F10: B | G10: Core | J10: {=IF($I10="","",IFERROR(INDEX(Legend!$C$41:$C$45,MATCH($I10,Legend!$B$41:$B$45,0)),""))}
A11: 7 | B11: Part 13 — Interview-Specific Practice | C11: 13.1 Polyfills & "implement it yourself" | D11: flatten(arr, depth) | E11: 1–3 | F11: B | G11: Core | J11: {=IF($I11="","",IFERROR(INDEX(Legend!$C$41:$C$45,MATCH($I11,Legend!$B$41:$B$45,0)),""))}
A12: 8 | B12: Part 13 — Interview-Specific Practice | C12: 13.1 Polyfills & "implement it yourself" | D12: curry / pipe / compose / memoize | E12: 1–3 | F12: B | G12: Core | J12: {=IF($I12="","",IFERROR(INDEX(Legend!$C$41:$C$45,MATCH($I12,Legend!$B$41:$B$45,0)),""))}
A13: 9 | B13: Part 13 — Interview-Specific Practice | C13: 13.1 Polyfills & "implement it yourself" | D13: new / instanceof / Object.create | E13: 1–3 | F13: B | G13: Common | J13: {=IF($I13="","",IFERROR(INDEX(Legend!$C$41:$C$45,MATCH($I13,Legend!$B$41:$B$45,0)),""))}
A14: 10 | B14: Part 13 — Interview-Specific Practice | C14: 13.1 Polyfills & "implement it yourself" | D14: groupBy, chunk, zip | E14: 1–3 | F14: B | G14: Common | J14: {=IF($I14="","",IFERROR(INDEX(Legend!$C$41:$C$45,MATCH($I14,Legend!$B$41:$B$45,0)),""))}
A15: 11 | B15: Part 13 — Interview-Specific Practice | C15: 13.1 Polyfills & "implement it yourself" | D15: Event emitter (on/off/emit) | E15: 1–3 | F15: B | G15: Common | J15: {=IF($I15="","",IFERROR(INDEX(Legend!$C$41:$C$45,MATCH($I15,Legend!$B$41:$B$45,0)),""))}
A16: 12 | B16: Part 13 — Interview-Specific Practice | C16: 13.1 Polyfills & "implement it yourself" | D16: typeof-style detectType | E16: 1–3 | F16: B | G16: Common | H16: FEM opens its interview course with it | J16: {=IF($I16="","",IFERROR(INDEX(Legend!$C$41:$C$45,MATCH($I16,Legend!$B$41:$B$45,0)),""))}
A17: 13 | B17: Part 13 — Interview-Specific Practice | C17: 13.2 Machine coding / component building (45–90 min rounds) | D17: Todo list with filters + persistence | E17: 1–3 | F17: B | G17: Core | J17: {=IF($I17="","",IFERROR(INDEX(Legend!$C$41:$C$45,MATCH($I17,Legend!$B$41:$B$45,0)),""))}
A18: 14 | B18: Part 13 — Interview-Specific Practice | C18: 13.2 Machine coding / component building (45–90 min rounds) | D18: Accordion | E18: 1–3 | F18: B | G18: Core | J18: {=IF($I18="","",IFERROR(INDEX(Legend!$C$41:$C$45,MATCH($I18,Legend!$B$41:$B$45,0)),""))}
A19: 15 | B19: Part 13 — Interview-Specific Practice | C19: 13.2 Machine coding / component building (45–90 min rounds) | D19: Tabs | E19: 1–3 | F19: B | G19: Core | J19: {=IF($I19="","",IFERROR(INDEX(Legend!$C$41:$C$45,MATCH($I19,Legend!$B$41:$B$45,0)),""))}
A20: 16 | B20: Part 13 — Interview-Specific Practice | C20: 13.2 Machine coding / component building (45–90 min rounds) | D20: Modal / dialog (with focus trap + Escape) | E20: 1–3 | F20: D | G20: Core | J20: {=IF($I20="","",IFERROR(INDEX(Legend!$C$41:$C$45,MATCH($I20,Legend!$B$41:$B$45,0)),""))}
A21: 17 | B21: Part 13 — Interview-Specific Practice | C21: 13.2 Machine coding / component building (45–90 min rounds) | D21: Star rating | E21: 1–3 | F21: B | G21: Core | H21: Both FEM and Scrimba use it | J21: {=IF($I21="","",IFERROR(INDEX(Legend!$C$41:$C$45,MATCH($I21,Legend!$B$41:$B$45,0)),""))}
A22: 18 | B22: Part 13 — Interview-Specific Practice | C22: 13.2 Machine coding / component building (45–90 min rounds) | D22: Autocomplete / typeahead with debounce + cancellation | E22: 1–3 | F22: B | G22: Core | H22: The most common single task | J22: {=IF($I22="","",IFERROR(INDEX(Legend!$C$41:$C$45,MATCH($I22,Legend!$B$41:$B$45,0)),""))}
A23: 19 | B23: Part 13 — Interview-Specific Practice | C23: 13.2 Machine coding / component building (45–90 min rounds) | D23: Infinite scroll (IntersectionObserver) | E23: 1–3 | F23: B | G23: Core | J23: {=IF($I23="","",IFERROR(INDEX(Legend!$C$41:$C$45,MATCH($I23,Legend!$B$41:$B$45,0)),""))}
A24: 20 | B24: Part 13 — Interview-Specific Practice | C24: 13.2 Machine coding / component building (45–90 min rounds) | D24: Pagination | E24: 1–3 | F24: B | G24: Core | J24: {=IF($I24="","",IFERROR(INDEX(Legend!$C$41:$C$45,MATCH($I24,Legend!$B$41:$B$45,0)),""))}
A25: 21 | B25: Part 13 — Interview-Specific Practice | C25: 13.2 Machine coding / component building (45–90 min rounds) | D25: Data table: sort, filter, paginate | E25: 1–3 | F25: B | G25: Core | J25: {=IF($I25="","",IFERROR(INDEX(Legend!$C$41:$C$45,MATCH($I25,Legend!$B$41:$B$45,0)),""))}
A26: 22 | B26: Part 13 — Interview-Specific Practice | C26: 13.2 Machine coding / component building (45–90 min rounds) | D26: Carousel / image gallery | E26: 1–3 | F26: B | G26: Common | J26: {=IF($I26="","",IFERROR(INDEX(Legend!$C$41:$C$45,MATCH($I26,Legend!$B$41:$B$45,0)),""))}
A27: 23 | B27: Part 13 — Interview-Specific Practice | C27: 13.2 Machine coding / component building (45–90 min rounds) | D27: Toast / notification system | E27: 1–3 | F27: B | G27: Common | J27: {=IF($I27="","",IFERROR(INDEX(Legend!$C$41:$C$45,MATCH($I27,Legend!$B$41:$B$45,0)),""))}
A28: 24 | B28: Part 13 — Interview-Specific Practice | C28: 13.2 Machine coding / component building (45–90 min rounds) | D28: Nested comments (recursive rendering) | E28: 1–3 | F28: B | G28: Common | J28: {=IF($I28="","",IFERROR(INDEX(Legend!$C$41:$C$45,MATCH($I28,Legend!$B$41:$B$45,0)),""))}
A29: 25 | B29: Part 13 — Interview-Specific Practice | C29: 13.2 Machine coding / component building (45–90 min rounds) | D29: OTP input | E29: 1–3 | F29: B | G29: Common | J29: {=IF($I29="","",IFERROR(INDEX(Legend!$C$41:$C$45,MATCH($I29,Legend!$B$41:$B$45,0)),""))}
A30: 26 | B30: Part 13 — Interview-Specific Practice | C30: 13.2 Machine coding / component building (45–90 min rounds) | D30: Progress bar / stepper / wizard | E30: 1–3 | F30: B | G30: Common | J30: {=IF($I30="","",IFERROR(INDEX(Legend!$C$41:$C$45,MATCH($I30,Legend!$B$41:$B$45,0)),""))}
A31: 27 | B31: Part 13 — Interview-Specific Practice | C31: 13.2 Machine coding / component building (45–90 min rounds) | D31: Tooltip with positioning | E31: 1–3 | F31: B | G31: Common | J31: {=IF($I31="","",IFERROR(INDEX(Legend!$C$41:$C$45,MATCH($I31,Legend!$B$41:$B$45,0)),""))}
A32: 28 | B32: Part 13 — Interview-Specific Practice | C32: 13.2 Machine coding / component building (45–90 min rounds) | D32: Shopping cart | E32: 1–3 | F32: B | G32: Common | J32: {=IF($I32="","",IFERROR(INDEX(Legend!$C$41:$C$45,MATCH($I32,Legend!$B$41:$B$45,0)),""))}
A33: 29 | B33: Part 13 — Interview-Specific Practice | C33: 13.2 Machine coding / component building (45–90 min rounds) | D33: Calculator | E33: 1–3 | F33: B | G33: Common | J33: {=IF($I33="","",IFERROR(INDEX(Legend!$C$41:$C$45,MATCH($I33,Legend!$B$41:$B$45,0)),""))}
A34: 30 | B34: Part 13 — Interview-Specific Practice | C34: 13.2 Machine coding / component building (45–90 min rounds) | D34: Stopwatch / countdown timer | E34: 1–3 | F34: B | G34: Common | J34: {=IF($I34="","",IFERROR(INDEX(Legend!$C$41:$C$45,MATCH($I34,Legend!$B$41:$B$45,0)),""))}
... A37: 33 | B37: Part 13 — Interview-Specific Practice | C37: 13.2 Machine coding / component building (45–90 min rounds) | D37: Chat UI with typing effect | E37: 1–3 | F37: E | G37: Rare | J37: {=IF($I37="","",IFERROR(INDEX(Legend!$C$41:$C$45,MATCH($I37,Legend!$B$41:$B$45,0)),""))}
A38: 34 | B38: Part 13 — Interview-Specific Practice | C38: 13.3 DSA-lite (what frontend rounds actually ask) | D38: Big-O: time & space | E38: 1–3 | F38: B | G38: Core | H38: Enough to justify a choice | J38: {=IF($I38="","",IFERROR(INDEX(Legend!$C$41:$C$45,MATCH($I38,Legend!$B$41:$B$45,0)),""))}
A39: 35 | B39: Part 13 — Interview-Specific Practice | C39: 13.3 DSA-lite (what frontend rounds actually ask) | D39: Array & string manipulation | E39: 1–3 | F39: B | G39: Core | H39: Anagram, palindrome, reverse, frequency count | J39: {=IF($I39="","",IFERROR(INDEX(Legend!$C$41:$C$45,MATCH($I39,Legend!$B$41:$B$45,0)),""))}
A40: 36 | B40: Part 13 — Interview-Specific Practice | C40: 13.3 DSA-lite (what frontend rounds actually ask) | D40: Hash maps for counting & lookup | E40: 1–3 | F40: B | G40: Core | H40: The single most useful technique here | J40: {=IF($I40="","",IFERROR(INDEX(Legend!$C$41:$C$45,MATCH($I40,Legend!$B$41:$B$45,0)),""))}
A41: 37 | B41: Part 13 — Interview-Specific Practice | C41: 13.3 DSA-lite (what frontend rounds actually ask) | D41: Two pointers / sliding window | E41: 1–3 | F41: B | G41: Common | J41: {=IF($I41="","",IFERROR(INDEX(Legend!$C$41:$C$45,MATCH($I41,Legend!$B$41:$B$45,0)),""))}
A42: 38 | B42: Part 13 — Interview-Specific Practice | C42: 13.3 DSA-lite (what frontend rounds actually ask) | D42: Sorting & custom comparators | E42: 1–3 | F42: B | G42: Core | J42: {=IF($I42="","",IFERROR(INDEX(Legend!$C$41:$C$45,MATCH($I42,Legend!$B$41:$B$45,0)),""))}
...

Sheet Course Map
A1: Course Map · where to actually study each part
A2: Scrimba for interactive reps, Master.dev for depth. You do not need both versions of the same topic — pick one and build something.
A3: Legend | B3: Core 0–5 | C3: Advanced | D3: Branches | E3: Drills | F3: ▸ Courses | G3: Dashboard
A4: Syllabus area | B4: Band | C4: Scrimba anchor | D4: Master.dev (Frontend Masters) anchor | E4: How to combine them
A5: HTML & CSS basics | B5: 0–1 | C5: Learn HTML and CSS; Frontend Path: Web dev basics | D5: Complete Intro to Web Development v3; Getting Started with CSS v2 | E5: One introductory sequence, then build a page nobody walked you through.
A6: Semantic HTML & a11y | B6: 0–3 | C6: Learn Accessible Web Design; Accessible development | D6: Website Accessibility v3 | E6: Reinforce semantics, then add keyboard and screen-reader passes to your own work.
A7: CSS fundamentals | B7: 0–3 | C7: Essential CSS concepts; Learn CSS Variables | D7: Modern CSS Fundamentals | E7: Skip repeated basics the moment you can debug the cascade and the box model.
A8: Layout & responsive | B8: 0–3 | C8: Learn Flexbox; Learn CSS Grid; Learn Responsive Web Design | D8: Ultimate CSS Grid & Layout Techniques v3; Practical CSS Layouts | E8: Use the newer course for subgrid and container queries.
A9: Visual implementation | B9: 1–3 | C9: Learn UI Design; Build Websites with Figma, HTML and CSS | D9: Professional CSS: Build a Website from Scratch; Design for Developers | E9: Learn to read a design, implement it, then compare side by side.
A10: CSS motion | B10: 1–3 | C10: Learn CSS Animations | D10: CSS Animations and Transitions; SVG Essentials & Animation v2 | E10: Transitions are core; sophisticated motion is a branch.
A11: Utility / preprocessor CSS | B11: Branch | C11: Learn Tailwind CSS; Learn Bootstrap | D11: Tailwind CSS 4+; Sass Fundamentals | E11: Learn whichever one the target team actually uses.
A12: JavaScript basics | B12: 0–1 | C12: Learn JavaScript; Making websites interactive | D12: Getting Started with JavaScript v3; JavaScript: From First Steps to Professional | E12: One thorough first pass, then practise without a tutorial open.
A13: Applied JavaScript | B13: 1–3 | C13: Advanced JavaScript; The Tricky Parts of JavaScript | D13: JavaScript: The Hard Parts v3; Deep JavaScript Foundations v3 | E13: This is where closures, this, prototypes, coercion and async ordering get precise.
A14: DOM & APIs | B14: 1–3 | C14: Working with APIs; APIs and Async JavaScript | D14: Vanilla JS: You Might Not Need a Framework | E14: Build one app with cancellation, failure states and real cleanup.
A15: Code quality | B15: 1–3 | C15: Introduction to Clean Code; Code reviews | D15: Functional JavaScript First Steps v2; A Tour of JS & React Patterns | E15: Apply three patterns to your own code instead of memorising twenty names.
... A37: Enterprise & leadership | B37: 5+ | C37: No direct equivalent | D37: Enterprise & Leadership; Code Architecture | E37: Advanced specialisation and team scope.

Sheet Dashboard
A1: Dashboard · progress by area
A2: Everything here is a live formula over the Core Syllabus sheet. Set Status there and these numbers move.
A3: Legend | B3: Core 0–5 | C3: Advanced | D3: Branches | E3: Drills | F3: Courses | G3: ▸ Dashboard
A5: Overall
A6: Items in the core syllabus | D6: =COUNTA('Core Syllabus'!$B$5:$B$1135) -> 1131
A7: Started (any status set) | D7: =COUNTIF('Core Syllabus'!$I$5:$I$1135,"<>") -> 0
A8: Solid | D8: =COUNTIF('Core Syllabus'!$I$5:$I$1135,"Solid") -> 0
A9: Average score (0–4) | D9: =IFERROR(AVERAGE('Core Syllabus'!$J$5:$J$1135),0) -> 0
A10: Percent solid | D10: =IFERROR(COUNTIF('Core Syllabus'!$I$5:$I$1135,"Solid")/COUNTA('Core Syllabus'!$B$5:$B$1135),0) -> 0
A12: By area · core syllabus
A13: Area | B13: Items | C13: Core | D13: Started | E13: Solid | F13: % solid | G13: Avg score
A14: Part 0 — How the Web Works | B14: =COUNTIF('Core Syllabus'!$B$5:$B$1135,$A14) -> 11 | C14: =COUNTIFS('Core Syllabus'!$B$5:$B$1135,$A14,'Core Syllabus'!$G$5:$G$1135,"Core") -> 5 | D14: =COUNTIFS('Core Syllabus'!$B$5:$B$1135,$A14,'Core Syllabus'!$I$5:$I$1135,"<>") -> 0 | E14: =COUNTIFS('Core Syllabus'!$B$5:$B$1135,$A14,'Core Syllabus'!$I$5:$I$1135,"Solid") -> 0 | F14: =IFERROR($E14/$B14,0) -> 0 | G14: =IFERROR(AVERAGEIF('Core Syllabus'!$B$5:$B$1135,$A14,'Core Syllabus'!$J$5:$J$1135),0) -> 0
A15: Part 1 — HTML | B15: =COUNTIF('Core Syllabus'!$B$5:$B$1135,$A15) -> 93 | C15: =COUNTIFS('Core Syllabus'!$B$5:$B$1135,$A15,'Core Syllabus'!$G$5:$G$1135,"Core") -> 41 | D15: =COUNTIFS('Core Syllabus'!$B$5:$B$1135,$A15,'Core Syllabus'!$I$5:$I$1135,"<>") -> 0 | E15: =COUNTIFS('Core Syllabus'!$B$5:$B$1135,$A15,'Core Syllabus'!$I$5:$I$1135,"Solid") -> 0 | F15: =IFERROR($E15/$B15,0) -> 0 | G15: =IFERROR(AVERAGEIF('Core Syllabus'!$B$5:$B$1135,$A15,'Core Syllabus'!$J$5:$J$1135),0) -> 0
A16: Part 2 — CSS | B16: =COUNTIF('Core Syllabus'!$B$5:$B$1135,$A16) -> 174 | C16: =COUNTIFS('Core Syllabus'!$B$5:$B$1135,$A16,'Core Syllabus'!$G$5:$G$1135,"Core") -> 102 | D16: =COUNTIFS('Core Syllabus'!$B$5:$B$1135,$A16,'Core Syllabus'!$I$5:$I$1135,"<>") -> 0 | E16: =COUNTIFS('Core Syllabus'!$B$5:$B$1135,$A16,'Core Syllabus'!$I$5:$I$1135,"Solid") -> 0 | F16: =IFERROR($E16/$B16,0) -> 0 | G16: =IFERROR(AVERAGEIF('Core Syllabus'!$B$5:$B$1135,$A16,'Core Syllabus'!$J$5:$J$1135),0) -> 0
A17: Part 2B — Implementing Designs | B17: =COUNTIF('Core Syllabus'!$B$5:$B$1135,$A17) -> 7 | C17: =COUNTIFS('Core Syllabus'!$B$5:$B$1135,$A17,'Core Syllabus'!$G$5:$G$1135,"Core") -> 4 | D17: =COUNTIFS('Core Syllabus'!$B$5:$B$1135,$A17,'Core Syllabus'!$I$5:$I$1135,"<>") -> 0 | E17: =COUNTIFS('Core Syllabus'!$B$5:$B$1135,$A17,'Core Syllabus'!$I$5:$I$1135,"Solid") -> 0 | F17: =IFERROR($E17/$B17,0) -> 0 | G17: =IFERROR(AVERAGEIF('Core Syllabus'!$B$5:$B$1135,$A17,'Core Syllabus'!$J$5:$J$1135),0) -> 0
A18: Part 3 — JavaScript: The Language | B18: =COUNTIF('Core Syllabus'!$B$5:$B$1135,$A18) -> 176 | C18: =COUNTIFS('Core Syllabus'!$B$5:$B$1135,$A18,'Core Syllabus'!$G$5:$G$1135,"Core") -> 110 | D18: =COUNTIFS('Core Syllabus'!$B$5:$B$1135,$A18,'Core Syllabus'!$I$5:$I$1135,"<>") -> 0 | E18: =COUNTIFS('Core Syllabus'!$B$5:$B$1135,$A18,'Core Syllabus'!$I$5:$I$1135,"Solid") -> 0 | F18: =IFERROR($E18/$B18,0) -> 0 | G18: =IFERROR(AVERAGEIF('Core Syllabus'!$B$5:$B$1135,$A18,'Core Syllabus'!$J$5:$J$1135),0) -> 0
A19: Part 4 — Browser, DOM & Web APIs | B19: =COUNTIF('Core Syllabus'!$B$5:$B$1135,$A19) -> 74 | C19: =COUNTIFS('Core Syllabus'!$B$5:$B$1135,$A19,'Core Syllabus'!$G$5:$G$1135,"Core") -> 45 | D19: =COUNTIFS('Core Syllabus'!$B$5:$B$1135,$A19,'Core Syllabus'!$I$5:$I$1135,"<>") -> 0 | E19: =COUNTIFS('Core Syllabus'!$B$5:$B$1135,$A19,'Core Syllabus'!$I$5:$I$1135,"Solid") -> 0 | F19: =IFERROR($E19/$B19,0) -> 0 | G19: =IFERROR(AVERAGEIF('Core Syllabus'!$B$5:$B$1135,$A19,'Core Syllabus'!$J$5:$J$1135),0) -> 0
A20: Part 5 — Asynchronous JavaScript & Networking | B20: =COUNTIF('Core Syllabus'!$B$5:$B$1135,$A20) -> 90 | C20: =COUNTIFS('Core Syllabus'!$B$5:$B$1135,$A20,'Core Syllabus'!$G$5:$G$1135,"Core") -> 58 | D20: =COUNTIFS('Core Syllabus'!$B$5:$B$1135,$A20,'Core Syllabus'!$I$5:$I$1135,"<>") -> 0 | E20: =COUNTIFS('Core Syllabus'!$B$5:$B$1135,$A20,'Core Syllabus'!$I$5:$I$1135,"Solid") -> 0 | F20: =IFERROR($E20/$B20,0) -> 0 | G20: =IFERROR(AVERAGEIF('Core Syllabus'!$B$5:$B$1135,$A20,'Core Syllabus'!$J$5:$J$1135),0) -> 0
A21: Part 6 — Tooling & Workflow | B21: =COUNTIF('Core Syllabus'!$B$5:$B$1135,$A21) -> 72 | C21: =COUNTIFS('Core Syllabus'!$B$5:$B$1135,$A21,'Core Syllabus'!$G$5:$G$1135,"Core") -> 41 | D21: =COUNTIFS('Core Syllabus'!$B$5:$B$1135,$A21,'Core Syllabus'!$I$5:$I$1135,"<>") -> 0 | E21: =COUNTIFS('Core Syllabus'!$B$5:$B$1135,$A21,'Core Syllabus'!$I$5:$I$1135,"Solid") -> 0 | F21: =IFERROR($E21/$B21,0) -> 0 | G21: =IFERROR(AVERAGEIF('Core Syllabus'!$B$5:$B$1135,$A21,'Core Syllabus'!$J$5:$J$1135),0) -> 0
A22: Part 7 — TypeScript | B22: =COUNTIF('Core Syllabus'!$B$5:$B$1135,$A22) -> 30 | C22: =COUNTIFS('Core Syllabus'!$B$5:$B$1135,$A22,'Core Syllabus'!$G$5:$G$1135,"Core") -> 21 | D22: =COUNTIFS('Core Syllabus'!$B$5:$B$1135,$A22,'Core Syllabus'!$I$5:$I$1135,"<>") -> 0 | E22: =COUNTIFS('Core Syllabus'!$B$5:$B$1135,$A22,'Core Syllabus'!$I$5:$I$1135,"Solid") -> 0 | F22: =IFERROR($E22/$B22,0) -> 0 | G22: =IFERROR(AVERAGEIF('Core Syllabus'!$B$5:$B$1135,$A22,'Core Syllabus'!$J$5:$J$1135),0) -> 0
A23: Part 8 — React | B23: =COUNTIF('Core Syllabus'!$B$5:$B$1135,$A23) -> 267 | C23: =COUNTIFS('Core Syllabus'!$B$5:$B$1135,$A23,'Core Syllabus'!$G$5:$G$1135,"Core") -> 183 | D23: =COUNTIFS('Core Syllabus'!$B$5:$B$1135,$A23,'Core Syllabus'!$I$5:$I$1135,"<>") -> 0 | E23: =COUNTIFS('Core Syllabus'!$B$5:$B$1135,$A23,'Core Syllabus'!$I$5:$I$1135,"Solid") -> 0 | F23: =IFERROR($E23/$B23,0) -> 0 | G23: =IFERROR(AVERAGEIF('Core Syllabus'!$B$5:$B$1135,$A23,'Core Syllabus'!$J$5:$J$1135),0) -> 0
A24: Part 9 — Accessibility | B24: =COUNTIF('Core Syllabus'!$B$5:$B$1135,$A24) -> 32 | C24: =COUNTIFS('Core Syllabus'!$B$5:$B$1135,$A24,'Core Syllabus'!$G$5:$G$1135,"Core") -> 21 | D24: =COUNTIFS('Core Syllabus'!$B$5:$B$1135,$A24,'Core Syllabus'!$I$5:$I$1135,"<>") -> 0 | E24: =COUNTIFS('Core Syllabus'!$B$5:$B$1135,$A24,'Core Syllabus'!$I$5:$I$1135,"Solid") -> 0 | F24: =IFERROR($E24/$B24,0) -> 0 | G24: =IFERROR(AVERAGEIF('Core Syllabus'!$B$5:$B$1135,$A24,'Core Syllabus'!$J$5:$J$1135),0) -> 0
A25: Part 10 — Web Performance | B25: =COUNTIF('Core Syllabus'!$B$5:$B$1135,$A25) -> 30 | C25: =COUNTIFS('Core Syllabus'!$B$5:$B$1135,$A25,'Core Syllabus'!$G$5:$G$1135,"Core") -> 20 | D25: =COUNTIFS('Core Syllabus'!$B$5:$B$1135,$A25,'Core Syllabus'!$I$5:$I$1135,"<>") -> 0 | E25: =COUNTIFS('Core Syllabus'!$B$5:$B$1135,$A25,'Core Syllabus'!$I$5:$I$1135,"Solid") -> 0 | F25: =IFERROR($E25/$B25,0) -> 0 | G25: =IFERROR(AVERAGEIF('Core Syllabus'!$B$5:$B$1135,$A25,'Core Syllabus'!$J$5:$J$1135),0) -> 0
... A29: Part 16 — Feature System Design | B29: =COUNTIF('Core Syllabus'!$B$5:$B$1135,$A29) -> 13 | C29: =COUNTIFS('Core Syllabus'!$B$5:$B$1135,$A29,'Core Syllabus'!$G$5:$G$1135,"Core") -> 12 | D29: =COUNTIFS('Core Syllabus'!$B$5:$B$1135,$A29,'Core Syllabus'!$I$5:$I$1135,"<>") -> 0 | E29: =COUNTIFS('Core Syllabus'!$B$5:$B$1135,$A29,'Core Syllabus'!$I$5:$I$1135,"Solid") -> 0 | F29: =IFERROR($E29/$B29,0) -> 0 | G29: =IFERROR(AVERAGEIF('Core Syllabus'!$B$5:$B$1135,$A29,'Core Syllabus'!$J$5:$J$1135),0) -> 0
A31: By band and by weight
A32: Band | B32: Items | C32: Solid | E32: Weight | F32: Items | G32: Solid
A33: 0–1 | B33: =COUNTIF('Core Syllabus'!$E$5:$E$1135,$A33) -> 180 | C33: =COUNTIFS('Core Syllabus'!$E$5:$E$1135,$A33,'Core Syllabus'!$I$5:$I$1135,"Solid") -> 0 | E33: Core | F33: =COUNTIF('Core Syllabus'!$G$5:$G$1135,$E33) -> 704 | G33: =COUNTIFS('Core Syllabus'!$G$5:$G$1135,$E33,'Core Syllabus'!$I$5:$I$1135,"Solid") -> 0
A34: 1–3 | B34: =COUNTIF('Core Syllabus'!$E$5:$E$1135,$A34) -> 933 | C34: =COUNTIFS('Core Syllabus'!$E$5:$E$1135,$A34,'Core Syllabus'!$I$5:$I$1135,"Solid") -> 0 | E34: Common | F34: =COUNTIF('Core Syllabus'!$G$5:$G$1135,$E34) -> 353 | G34: =COUNTIFS('Core Syllabus'!$G$5:$G$1135,$E34,'Core Syllabus'!$I$5:$I$1135,"Solid") -> 0
A35: 3–5 | B35: =COUNTIF('Core Syllabus'!$E$5:$E$1135,$A35) -> 18 | C35: =COUNTIFS('Core Syllabus'!$E$5:$E$1135,$A35,'Core Syllabus'!$I$5:$I$1135,"Solid") -> 0 | E35: Rare | F35: =COUNTIF('Core Syllabus'!$G$5:$G$1135,$E35) -> 74 | G35: =COUNTIFS('Core Syllabus'!$G$5:$G$1135,$E35,'Core Syllabus'!$I$5:$I$1135,"Solid") -> 0
A37: Other sheets
A38: Sheet | B38: Items
A39: Advanced Web (5+ / specialist) | B39: =COUNTA('Advanced Web'!$B$5:$B$62) -> 58
A40: Role Branches | B40: =COUNTA('Role Branches'!$B$5:$B$310) -> 306
A41: Interview Drills | B41: =COUNTA('Interview Drills'!$B$5:$B$66) -> 62
